Workbook

Sheet Plano Diário
A1: Data | B1: Dia da semana | C1: Semana | D1: Tipo de dia | E1: Tema macro | F1: Ângulo/Trilha | G1: Categoria | H1: Canal/Área | I1: O que | J1: Como | K1: Onde | L1: CTA | M1: Descrição da ação | N1: Duração (min) | O1: Prioridade | P1: KPI/Meta | Q1: Status | R1: Mês
A2: 46023 | B2: quinta-feira | C2: Semana Setup | D2: Terça–Sexta – Operação & Growth | E2: Setup inicial (HUB, cupons, padrões) | F2: Gestão Comercial | G2: Setup | H2: WordPress | I2: Criar página HUB /trilhas (estrutura base) | J2: Páginas > Adicionar nova > slug 'trilhas'. Inserir seções: Por onde começar, Trilhas, Cursos, FAQ. | K2: WordPress | L2: CTA: /trilhas | M2: Publicar versão 1 (pode melhorar depois). | N2: 120 | O2: Alta | P2: HUB no ar | Q2: Feito | R2: =MONTH(Tabela1[[#This Row],[Data]]) -> 1
A3: 46023 | B3: quinta-feira | C3: Semana Setup | D3: Terça–Sexta – Operação & Growth | E3: Setup inicial (HUB, cupons, padrões) | F3: Gestão Comercial | G3: Setup | H3: WordPress | I3: Instalar plugin Redirection e criar /go/* (links curtos) | J3: Plugins > Adicionar > Redirection. Criar redirecionamentos /go/dre, /go/fc, /go/jbp, /go/escuta, etc. | K3: WordPress/Redirection | L3: CTA: /trilhas | M3: Permite trocar cupons sem editar a página HUB. | N3: 90 | O3: Alta | P3: Links /go ativos | Q3: Feito | R3: =MONTH(Tabela1[[#This Row],[Data]]) -> 1
A4: 46024 | B4: sexta-feira | C4: Semana Setup | D4: Terça–Sexta – Operação & Growth | E4: Setup inicial (HUB, cupons, padrões) | F4: Gestão Comercial | G4: Setup | H4: Métricas | I4: Instalar GA4 via Site Kit + configurar Search Console | J4: Instalar plugin Site Kit by Google, conectar Analytics e Search Console. Validar pageview em /trilhas. | K4: WordPress + Google | L4: Sem CTA | M4: Medição mínima pronta. | N4: 90 | O4: Alta | P4: GA4 coletando | Q4: Fazendo | R4: =MONTH(Tabela1[[#This Row],[Data]]) -> 1
A5: 46024 | B5: sexta-feira | C5: Semana Setup | D5: Terça–Sexta – Operação & Growth | E5: Setup inicial (HUB, cupons, padrões) | F5: Gestão Comercial | G5: Setup | H5: Udemy | I5: Criar cupons BASE (30 dias) para todos os cursos + registrar nomes | J5: Criar cupons base: DRE, FC, JBP, Escuta, Negociação, Varejo, JBP Gestores, Precificação, Custo Entrega. | K5: Udemy Instructor | L5: CTA: /trilhas | M5: Defina ticket base (ex.: R$149–R$199) e nomenclatura por canal. | N5: 120 | O5: Alta | P5: Cupons base ativos | Q5: Feito | R5: =MONTH(Tabela1[[#This Row],[Data]]) -> 1
A6: 46023 | B6: quinta-feira | C6: Semana Setup | E6: Gravação do Curso de Negociação | O6: Alta | Q6: A fazer | R6: =MONTH(Tabela1[[#This Row],[Data]]) -> 1
A7: 46024 | B7: segunda-feira | C7: Semana 2 (05/01–10/01) | E7: Gravação do Curso JBP para Gestores | O7: Alta | Q7: A fazer | R7: =MONTH(Tabela1[[#This Row],[Data]]) -> 1
A8: 46025 | B8: segunda-feira | C8: Semana 2 (05/01–10/01) | E8: Estrutura e conteúdo curso o essencial formação de preço | J8: ver projeto growth no claude | O8: Alta | Q8: A fazer | R8: =MONTH(Tabela1[[#This Row],[Data]]) -> 1
A9: 46026 | B9: segunda-feira | C9: Semana 2 (05/01–10/01) | E9: Estrutura e conteúdo curso o essencial custo de entrega | J9: ver projeto growth no claude | O9: Alta | Q9: A fazer | R9: =MONTH(Tabela1[[#This Row],[Data]]) -> 1
A10: 46025 | B10: sábado | C10: Semana 2 (05/01–10/01) | D10: Sábado – Planejamento (próxima semana) | E10: Seu DRE é um dedo-duro: o que ele revela em 15 min | F10: Financeiro | G10: Setup | H10: Udemy | I10: Padronizar Bonus Lecture (modelo) nos cursos já publicados | J10: Inserir a última aula com próximos passos por trilha + links permitidos (cupons/referral). | K10: Udemy Instructor | L10: CTA: links na Bonus Lecture | M10: Aumenta cross-sell e vendas em todos os cursos. | N10: 150 | O10: Alta | P10: Bonus Lecture padrão | Q10: A fazer | R10: =MONTH(Tabela1[[#This Row],[Data]]) -> 1
A11: 46025 | B11: sábado | C11: Semana 2 (05/01–10/01) | D11: Sábado – Planejamento (próxima semana) | E11: Seu DRE é um dedo-duro: o que ele revela em 15 min | F11: Transversal (planejar 3 ângulos) | G11: Planejamento | H11: Editorial | I11: Definir tema macro + 3 ângulos (trilhas) + CTA da semana | J11: Escolher 1 tema macro e escrever 3 ângulos: Financeiro, Negociação/Vendas, Gestão Comercial. Definir CTA. | K11: Documento/Notion/Excel | L11: CTA: /trilhas (botão DRE) + /go/dre | M11: Tema da próxima semana: Seu DRE é um dedo-duro: o que ele revela em 15 min. | N11: 70 | O11: Alta | P11: Tema fechado | Q11: A fazer | R11: =MONTH(Tabela1[[#This Row],[Data]]) -> 1
A12: 46025 | B12: sábado | C12: Semana 2 (05/01–10/01) | D12: Sábado – Planejamento (próxima semana) | E12: Seu DRE é um dedo-duro: o que ele revela em 15 min | F12: Transversal (planejar 3 ângulos) | G12: Planejamento | H12: Roteiro | I12: Esboçar vídeo YouTube + cortes + posts | J12: Criar: título do vídeo, 3 bullets, exemplo prático, checklist final. Definir 2 hooks de posts LI e páginas do carrossel. | K12: GPT/Claude + rascunho | L12: CTA: /trilhas | M12: Sai do sábado com o pacote pronto para produzir na segunda. | N12: 80 | O12: Alta | P12: Roteiro pronto | Q12: A fazer | R12: =MONTH(Tabela1[[#This Row],[Data]]) -> 1
A13: 46025 | B13: sábado | C13: Semana 2 (05/01–10/01) | D13: Sábado – Planejamento (próxima semana) | E13: Seu DRE é um dedo-duro: o que ele revela em 15 min | F13: Transversal (planejar 3 ângulos) | G13: Planejamento | H13: Cupons | I13: Planejar cupons (base/campanha) e tarefas Udemy da semana | J13: Se semana de campanha, preparar cupom campanha e texto do e-mail promocional. Se não, garantir base ativa. | K13: Udemy Instructor (rascunho) | L13: CTA: /trilhas | M13: Evita pressa na segunda. Se necessário, rascunhe e-mail promocional. | N13: 35 | O13: Média | P13: Cupons planejados | Q13: A fazer | R13: =MONTH(Tabela1[[#This Row],[Data]]) -> 1
A14: 46027 | B14: segunda-feira | C14: Semana 2 (05/01–10/01) | D14: Segunda – Produção & Programação | E14: Seu DRE é um dedo-duro: o que ele revela em 15 min | F14: Transversal (3 ângulos) | G14: Conteúdo | H14: YouTube | I14: Vídeo longo (8–12 min) – roteiro+gravação+upload rascunho | J14: Use GPT/Claude para roteiro; grave em lote; faça uma tomada principal; suba como rascunho no YouTube e programe. | K14: YouTube Studio + Filmora | L14: CTA na descrição e comentário fixado → phdonassolo.com/trilhas | M14: Tema macro: Seu DRE é um dedo-duro: o que ele revela em 15 min. Objetivo: gerar autoridade e cliques para o HUB. Inclua 1 exemplo prático + checklist. | N14: 150 | O14: Alta | P14: Visualizações + cliques em /trilhas | Q14: A fazer | R14: =MONTH(Tabela1[[#This Row],[Data]]) -> 1
A15: 46027 | B15: segunda-feira | C15: Semana 2 (05/01–10/01) | D15: Segunda – Produção & Programação | E15: Seu DRE é um dedo-duro: o que ele revela em 15 min | F15: Transversal (3 ângulos) | G15: Conteúdo | H15: YouTube Shorts/Reels | I15: 2 cortes (30–60s) do vídeo – editar e agendar | J15: Corte 2 trechos (gancho + dica). Legenda curta. Programe 1 para terça e 1 para quinta. | K15: YouTube Shorts + IG Reels | L15: CTA: /trilhas + curso foco da semana | M15: Reaproveitar o vídeo longo. Gancho forte nos 2 primeiros segundos. | N15: 60 | O15: Alta | P15: Retenção e cliques | Q15: A fazer | R15: =MONTH(Tabela1[[#This Row],[Data]]) -> 1
A16: 46027 | B16: segunda-feira | C16: Semana 2 (05/01–10/01) | D16: Segunda – Produção & Programação | E16: Seu DRE é um dedo-duro: o que ele revela em 15 min | F16: Transversal (3 ângulos) | G16: Conteúdo | H16: LinkedIn | I16: 2 posts texto (ter e sex) – escrever e agendar | J16: Modelo: dor → mini-framework → exemplo → CTA. Varie: 1 mais técnico, 1 mais narrativo. | K16: LinkedIn | L16: CTA: phdonassolo.com/trilhas (botão da trilha/curso foco) | M16: Use o tema macro e o ângulo das trilhas no texto. Inclua 1 pergunta no final. | N16: 60 | O16: Alta | P16: Alcance + comentários | Q16: A fazer | R16: =MONTH(Tabela1[[#This Row],[Data]]) -> 1
A17: 46027 | B17: segunda-feira | C17: Semana 2 (05/01–10/01) | D17: Segunda – Produção & Programação | E17: Seu DRE é um dedo-duro: o que ele revela em 15 min | F17: Transversal (3 ângulos) | G17: Conteúdo | H17: LinkedIn/IG/FB | I17: 1 carrossel (qui) – criar + adaptar para IG/FB e agendar | J17: Estrutura 7–9 páginas: gancho, 3 erros, 3 correções, checklist, CTA. Criar no Canva. | K17: Canva + LinkedIn + Meta Business Suite | L17: CTA: /trilhas + curso foco | M17: Carrossel deve ser didático, com frases curtas e exemplo prático. | N17: 90 | O17: Alta | P17: Salvamentos + cliques | Q17: A fazer | R17: =MONTH(Tabela1[[#This Row],[Data]]) -> 1
A18: 46027 | B18: segunda-feira | C18: Semana 2 (05/01–10/01) | D18: Segunda – Produção & Programação | E18: Seu DRE é um dedo-duro: o que ele revela em 15 min | F18: Financeiro | G18: Growth | H18: HUB/Links | I18: Checklist de links e CTAs da semana (sem troca de cupom) | J18: Teste botões do /trilhas e redirecionamentos /go. Ajuste se necessário. | K18: WordPress | L18: CTA: /trilhas | M18: Evita perda de venda por link quebrado; ajuste rápido. | N18: 20 | O18: Média | P18: 0 links quebrados | Q18: A fazer | R18: =MONTH(Tabela1[[#This Row],[Data]]) -> 1
A19: 46028 | B19: terça-feira | C19: Semana 2 (05/01–10/01) | D19: Terça–Sexta – Operação & Growth | E19: Seu DRE é um dedo-duro: o que ele revela em 15 min | F19: Financeiro | G19: Operação | H19: Udemy | I19: Rotina Q&A e avaliações (SLA 24h) | J19: Responder perguntas, agradecer feedback, sinalizar melhorias. Registrar pontos recorrentes. | K19: Udemy Instructor | L19: Sem CTA (suporte) | M19: Manter satisfação e nota. Separe dúvidas por curso para futuras melhorias. | N19: 30 | O19: Alta | P19: Tempo de resposta <24h | Q19: A fazer | R19: =MONTH(Tabela1[[#This Row],[Data]]) -> 1
A20: 46028 | B20: terça-feira | C20: Semana 2 (05/01–10/01) | D20: Terça–Sexta – Operação & Growth | E20: Seu DRE é um dedo-duro: o que ele revela em 15 min | F20: Financeiro | G20: Growth | H20: Udemy | I20: Anúncio educacional (1/semana) – mini-aula + tarefa | J20: Enviar 1 anúncio educacional para o curso mais alinhado ao tema da semana. Sem links para outros cursos. | K20: Udemy Instructor | L20: CTA interno: 'aplique a tarefa' (sem venda) | M20: Conteúdo educacional sobre: Seu DRE é um dedo-duro: o que ele revela em 15 min. Inclua exercício de 10–15 min. | N20: 30 | O20: Alta | P20: Engajamento / conclusão | Q20: A fazer | R20: =MONTH(Tabela1[[#This Row],[Data]]) -> 1
A21: 46028 | B21: terça-feira | C21: Semana 2 (05/01–10/01) | D21: Terça–Sexta – Operação & Growth | E21: Seu DRE é um dedo-duro: o que ele revela em 15 min | F21: Financeiro | G21: Operação | H21: Social | I21: Engajamento 20-min: comentar em 10 posts de decisores | J21: Comente com valor (exemplo, pergunta, complemento). 0 autopromoção direta. | K21: LinkedIn | L21: CTA indireto: perfil + /trilhas no destaque | M21: Objetivo: alcance orgânico e novas conexões qualificadas. | N21: 20 | O21: Média | P21: Novas conexões/semana | Q21: A fazer | R21: =MONTH(Tabela1[[#This Row],[Data]]) -> 1
... A47: 46038 | B47: sexta-feira | C47: Semana 3 (12/01–17/01) | D47: Terça–Sexta – Operação & Growth | E47: Negociação sem improviso: valor antes do preço | F47: Gestão Comercial | G47: Operação | H47: HUB | I47: Auditoria rápida do /trilhas (UX) | J47: Verificar ordem dos botões, clareza de trilhas e links. Ajustar texto se necessário. | K47: WordPress | L47: CTA: /trilhas | M47: Pequenos ajustes aumentam conversão. | N47: 20 | O47: Média | P47: Tempo na página / cliques | Q47: A fazer | R47: =MONTH(Tabela1[[#This Row],[Data]]) -> 1
A48: 45674 | B48: Sabado | C48: Semana 3 (12/01–17/01) | D48: Sábado – Planejamento (próxima semana) | E48: Publicar os novos cursos, publicitar para os alunos e criar bundles. | R48: =MONTH(Tabela1[[#This Row],[Data]]) -> 1
A49: 46039 | B49: sábado | C49: Semana 4 (19/01–24/01) | D49: Sábado – Planejamento (próxima semana) | E49: Gestão de loja para PMEs: giro, margem e rotina | F49: Transversal (planejar 3 ângulos) | G49: Planejamento | H49: Editorial | I49: Definir tema macro + 3 ângulos (trilhas) + CTA da semana | J49: Escolher 1 tema macro e escrever 3 ângulos: Financeiro, Negociação/Vendas, Gestão Comercial. Definir CTA. | K49: Documento/Notion/Excel | L49: CTA: /trilhas (botão Varejo) + /go/varejo | M49: Tema da próxima semana: Gestão de loja para PMEs: giro, margem e rotina. | N49: 70 | O49: Alta | P49: Tema fechado | Q49: A fazer | R49: =MONTH(Tabela1[[#This Row],[Data]]) -> 1
A50: 46039 | B50: sábado | C50: Semana 4 (19/01–24/01) | D50: Sábado – Planejamento (próxima semana) | E50: Gestão de loja para PMEs: giro, margem e rotina | F50: Transversal (planejar 3 ângulos) | G50: Planejamento | H50: Roteiro | I50: Esboçar vídeo YouTube + cortes + posts | J50: Criar: título do vídeo, 3 bullets, exemplo prático, checklist final. Definir 2 hooks de posts LI e páginas do carrossel. | K50: GPT/Claude + rascunho | L50: CTA: /trilhas | M50: Sai do sábado com o pacote pronto para produzir na segunda. | N50: 80 | O50: Alta | P50: Roteiro pronto | Q50: A fazer | R50: =MONTH(Tabela1[[#This Row],[Data]]) -> 1
A51: 46039 | B51: sábado | C51: Semana 4 (19/01–24/01) | D51: Sábado – Planejamento (próxima semana) | E51: Gestão de loja para PMEs: giro, margem e rotina | F51: Transversal (planejar 3 ângulos) | G51: Planejamento | H51: Cupons | I51: Planejar cupons (base/campanha) e tarefas Udemy da semana | J51: Se semana de campanha, preparar cupom campanha e texto do e-mail promocional. Se não, garantir base ativa. | K51: Udemy Instructor (rascunho) | L51: CTA: /trilhas | M51: Evita pressa na segunda. Se necessário, rascunhe e-mail promocional. | N51: 35 | O51: Média | P51: Cupons planejados | Q51: A fazer | R51: =MONTH(Tabela1[[#This Row],[Data]]) -> 1
A52: 46041 | B52: segunda-feira | C52: Semana 4 (19/01–24/01) | D52: Segunda – Produção & Programação | E52: Gestão de loja para PMEs: giro, margem e rotina | F52: Transversal (3 ângulos) | G52: Conteúdo | H52: YouTube | I52: Vídeo longo (8–12 min) – roteiro+gravação+upload rascunho | J52: Use GPT/Claude para roteiro; grave em lote; faça uma tomada principal; suba como rascunho no YouTube e programe. | K52: YouTube Studio + Filmora | L52: CTA na descrição e comentário fixado → phdonassolo.com/trilhas | M52: Tema macro: Gestão de loja para PMEs: giro, margem e rotina. Objetivo: gerar autoridade e cliques para o HUB. Inclua 1 exemplo prático + checklist. | N52: 150 | O52: Alta | P52: Visualizações + cliques em /trilhas | Q52: A fazer | R52: =MONTH(Tabela1[[#This Row],[Data]]) -> 1
A53: 46041 | B53: segunda-feira | C53: Semana 4 (19/01–24/01) | D53: Segunda – Produção & Programação | E53: Gestão de loja para PMEs: giro, margem e rotina | F53: Transversal (3 ângulos) | G53: Conteúdo | H53: YouTube Shorts/Reels | I53: 2 cortes (30–60s) do vídeo – editar e agendar | J53: Corte 2 trechos (gancho + dica). Legenda curta. Programe 1 para terça e 1 para quinta. | K53: YouTube Shorts + IG Reels | L53: CTA: /trilhas + curso foco da semana | M53: Reaproveitar o vídeo longo. Gancho forte nos 2 primeiros segundos. | N53: 60 | O53: Alta | P53: Retenção e cliques | Q53: A fazer | R53: =MONTH(Tabela1[[#This Row],[Data]]) -> 1
A54: 46041 | B54: segunda-feira | C54: Semana 4 (19/01–24/01) | D54: Segunda – Produção & Programação | E54: Gestão de loja para PMEs: giro, margem e rotina | F54: Transversal (3 ângulos) | G54: Conteúdo | H54: LinkedIn | I54: 2 posts texto (ter e sex) – escrever e agendar | J54: Modelo: dor → mini-framework → exemplo → CTA. Varie: 1 mais técnico, 1 mais narrativo. | K54: LinkedIn | L54: CTA: phdonassolo.com/trilhas (botão da trilha/curso foco) | M54: Use o tema macro e o ângulo das trilhas no texto. Inclua 1 pergunta no final. | N54: 60 | O54: Alta | P54: Alcance + comentários | Q54: A fazer | R54: =MONTH(Tabela1[[#This Row],[Data]]) -> 1
A55: 46041 | B55: segunda-feira | C55: Semana 4 (19/01–24/01) | D55: Segunda – Produção & Programação | E55: Gestão de loja para PMEs: giro, margem e rotina | F55: Transversal (3 ângulos) | G55: Conteúdo | H55: LinkedIn/IG/FB | I55: 1 carrossel (qui) – criar + adaptar para IG/FB e agendar | J55: Estrutura 7–9 páginas: gancho, 3 erros, 3 correções, checklist, CTA. Criar no Canva. | K55: Canva + LinkedIn + Meta Business Suite | L55: CTA: /trilhas + curso foco | M55: Carrossel deve ser didático, com frases curtas e exemplo prático. | N55: 90 | O55: Alta | P55: Salvamentos + cliques | Q55: A fazer | R55: =MONTH(Tabela1[[#This Row],[Data]]) -> 1
A56: 46041 | B56: segunda-feira | C56: Semana 4 (19/01–24/01) | D56: Segunda – Produção & Programação | E56: Gestão de loja para PMEs: giro, margem e rotina | F56: Gestão Comercial | G56: Growth | H56: Cupons/HUB | I56: Ativar cupom de CAMPANHA (7 dias) e atualizar links /go/* | J56: Crie cupom campanha na Udemy (7 dias) para o(s) curso(s) foco. Atualize targets no Redirection. | K56: Udemy Instructor + WordPress/Redirection | L56: CTA em todos os conteúdos → /trilhas | M56: Campanha ativa esta semana. Garanta que todos os CTAs usem cupom correto via /go/. | N56: 35 | O56: Alta | P56: Matrículas por cupom | Q56: A fazer | R56: =MONTH(Tabela1[[#This Row],[Data]]) -> 1
A57: 46042 | B57: terça-feira | C57: Semana 4 (19/01–24/01) | D57: Terça–Sexta – Operação & Growth | E57: Gestão de loja para PMEs: giro, margem e rotina | F57: Gestão Comercial | G57: Operação | H57: Udemy | I57: Rotina Q&A e avaliações (SLA 24h) | J57: Responder perguntas, agradecer feedback, sinalizar melhorias. Registrar pontos recorrentes. | K57: Udemy Instructor | L57: Sem CTA (suporte) | M57: Manter satisfação e nota. Separe dúvidas por curso para futuras melhorias. | N57: 30 | O57: Alta | P57: Tempo de resposta <24h | Q57: A fazer | R57: =MONTH(Tabela1[[#This Row],[Data]]) -> 1
A58: 46042 | B58: terça-feira | C58: Semana 4 (19/01–24/01) | D58: Terça–Sexta – Operação & Growth | E58: Gestão de loja para PMEs: giro, margem e rotina | F58: Gestão Comercial | G58: Growth | H58: Udemy | I58: Anúncio educacional (1/semana) – mini-aula + tarefa | J58: Enviar 1 anúncio educacional para o curso mais alinhado ao tema da semana. Sem links para outros cursos. | K58: Udemy Instructor | L58: CTA interno: 'aplique a tarefa' (sem venda) | M58: Conteúdo educacional sobre: Gestão de loja para PMEs: giro, margem e rotina. Inclua exercício de 10–15 min. | N58: 30 | O58: Alta | P58: Engajamento / conclusão | Q58: A fazer | R58: =MONTH(Tabela1[[#This Row],[Data]]) -> 1
A59: 46042 | B59: terça-feira | C59: Semana 4 (19/01–24/01) | D59: Terça–Sexta – Operação & Growth | E59: Gestão de loja para PMEs: giro, margem e rotina | F59: Gestão Comercial | G59: Operação | H59: Social | I59: Engajamento 20-min: comentar em 10 posts de decisores | J59: Comente com valor (exemplo, pergunta, complemento). 0 autopromoção direta. | K59: LinkedIn | L59: CTA indireto: perfil + /trilhas no destaque | M59: Objetivo: alcance orgânico e novas conexões qualificadas. | N59: 20 | O59: Média | P59: Novas conexões/semana | Q59: A fazer | R59: =MONTH(Tabela1[[#This Row],[Data]]) -> 1
A60: 46043 | B60: quarta-feira | C60: Semana 4 (19/01–24/01) | D60: Terça–Sexta – Operação & Growth | E60: Gestão de loja para PMEs: giro, margem e rotina | F60: Gestão Comercial | G60: Growth | H60: Métricas | I60: Registrar KPIs parciais da semana + leitura rápida | J60: Coletar: matrículas por curso, ticket efetivo por cupom, reviews, cliques em /trilhas (GA4). | K60: Udemy + GA4 | L60: Sem CTA | M60: Atualize painel semanal e identifique 1 ajuste para amanhã. | N60: 35 | O60: Alta | P60: KPIs atualizados | Q60: A fazer | R60: =MONTH(Tabela1[[#This Row],[Data]]) -> 1
... A86: 46052 | B86: sexta-feira | C86: Semana 5 (26/01–31/01) | D86: Terça–Sexta – Operação & Growth | E86: Execução comercial em 7 dias: pare de planejar e comece a rodar | F86: Gestão Comercial | G86: Operação | H86: HUB | I86: Auditoria rápida do /trilhas (UX) | J86: Verificar ordem dos botões, clareza de trilhas e links. Ajustar texto se necessário. | K86: WordPress | L86: CTA: /trilhas | M86: Pequenos ajustes aumentam conversão. | N86: 20 | O86: Média | P86: Tempo na página / cliques | Q86: A fazer | R86: =MONTH(Tabela1[[#This Row],[Data]]) -> 1
A87: 45688 | E87: Revisar e incluir ferramenta Curso Fluxo de Caixa: quem sabe prompt para IA analisar ou sugerir? Enviar email para os alunos e sugerir cupom para DRE | R87: =MONTH(Tabela1[[#This Row],[Data]]) -> 1
A88: 45688 | E88: Revisar e incluir ferramenta Curso DRE: quem sabe prompt para IA analisar ou sugerir? Enviar e-mail de atualização para os alunos e sugerir cupon para o curso de FC | R88: =MONTH(Tabela1[[#This Row],[Data]]) -> 1
A89: 45688 | E89: Oferecer cupons free para cross selling e recomendações para os cursos com pouca venda | R89: =MONTH(Tabela1[[#This Row],[Data]]) -> 1
A90: 46053 | B90: sábado | C90: Semana 6 (02/02–07/02) | D90: Sábado – Planejamento (próxima semana) | E90: Fluxo de caixa: previsibilidade em 15 minutos por semana | F90: Transversal (planejar 3 ângulos) | G90: Planejamento | H90: Editorial | I90: Definir tema macro + 3 ângulos (trilhas) + CTA da semana | J90: Escolher 1 tema macro e escrever 3 ângulos: Financeiro, Negociação/Vendas, Gestão Comercial. Definir CTA. | K90: Documento/Notion/Excel | L90: CTA: /trilhas (botão Fluxo de Caixa) + /go/fc | M90: Tema da próxima semana: Fluxo de caixa: previsibilidade em 15 minutos por semana. | N90: 70 | O90: Alta | P90: Tema fechado | Q90: A fazer | R90: =MONTH(Tabela1[[#This Row],[Data]]) -> 1
...

Sheet Filtro
A2: Data | C2: Status
A4: 46034 | C4: A fazer
A6: Data | B6: Dia da semana | C6: Semana | D6: Tipo de dia | E6: Tema macro | F6: Ângulo/Trilha | G6: Categoria | H6: Canal/Área | I6: O que | J6: Como | K6: Onde | L6: CTA | M6: Descrição da ação | N6: Duração (min) | O6: Prioridade | P6: KPI/Meta | Q6: Status | R6: Mês
A7: {=_xlfn._xlws.FILTER('Plano Diário'!A2:Q10002, ('Plano Diário'!A2:A10002 = Filtro!A4) * ((Filtro!C4 = "Todos") * ('Plano Diário'!Q2:Q10002 <> "Feito") + ('Plano Diário'!Q2:Q10002 = Filtro!C4)))} -> 46034 | B7: segunda-feira | C7: Semana 3 (12/01–17/01) | D7: Segunda – Produção & Programação | E7: Negociação sem improviso: valor antes do preço | F7: Transversal (3 ângulos) | G7: Conteúdo | H7: YouTube | I7: Vídeo longo (8–12 min) – roteiro+gravação+upload rascunho | J7: Use GPT/Claude para roteiro; grave em lote; faça uma tomada principal; suba como rascunho no YouTube e programe. | K7: YouTube Studio + Filmora | L7: CTA na descrição e comentário fixado → phdonassolo.com/trilhas | M7: Tema macro: Negociação sem improviso: valor antes do preço. Objetivo: gerar autoridade e cliques para o HUB. Inclua 1 exemplo prático + checklist. | N7: 150 | O7: Alta | P7: Visualizações + cliques em /trilhas | Q7: A fazer
A8: 46034 | B8: segunda-feira | C8: Semana 3 (12/01–17/01) | D8: Segunda – Produção & Programação | E8: Negociação sem improviso: valor antes do preço | F8: Transversal (3 ângulos) | G8: Conteúdo | H8: YouTube Shorts/Reels | I8: 2 cortes (30–60s) do vídeo – editar e agendar | J8: Corte 2 trechos (gancho + dica). Legenda curta. Programe 1 para terça e 1 para quinta. | K8: YouTube Shorts + IG Reels | L8: CTA: /trilhas + curso foco da semana | M8: Reaproveitar o vídeo longo. Gancho forte nos 2 primeiros segundos. | N8: 60 | O8: Alta | P8: Retenção e cliques | Q8: A fazer
A9: 46034 | B9: segunda-feira | C9: Semana 3 (12/01–17/01) | D9: Segunda – Produção & Programação | E9: Negociação sem improviso: valor antes do preço | F9: Transversal (3 ângulos) | G9: Conteúdo | H9: LinkedIn | I9: 2 posts texto (ter e sex) – escrever e agendar | J9: Modelo: dor → mini-framework → exemplo → CTA. Varie: 1 mais técnico, 1 mais narrativo. | K9: LinkedIn | L9: CTA: phdonassolo.com/trilhas (botão da trilha/curso foco) | M9: Use o tema macro e o ângulo das trilhas no texto. Inclua 1 pergunta no final. | N9: 60 | O9: Alta | P9: Alcance + comentários | Q9: A fazer
A10: 46034 | B10: segunda-feira | C10: Semana 3 (12/01–17/01) | D10: Segunda – Produção & Programação | E10: Negociação sem improviso: valor antes do preço | F10: Transversal (3 ângulos) | G10: Conteúdo | H10: LinkedIn/IG/FB | I10: 1 carrossel (qui) – criar + adaptar para IG/FB e agendar | J10: Estrutura 7–9 páginas: gancho, 3 erros, 3 correções, checklist, CTA. Criar no Canva. | K10: Canva + LinkedIn + Meta Business Suite | L10: CTA: /trilhas + curso foco | M10: Carrossel deve ser didático, com frases curtas e exemplo prático. | N10: 90 | O10: Alta | P10: Salvamentos + cliques | Q10: A fazer
A11: 46034 | B11: segunda-feira | C11: Semana 3 (12/01–17/01) | D11: Segunda – Produção & Programação | E11: Linktree ver Instagram Cacau Corazza | F11: Gestão Comercial | G11: Setup | H11: Métricas | I11: Criar o linktree para o site, LinkedIn, alguns cursos | J11: Criar o linktree para o site, LinkedIn, alguns cursos | K11: Instagram | L11: CTA conheça | M11: Linktree | N11: 30 | O11: Alta | P11: Cliques no botão | Q11: A fazer
A12: 46034 | B12: segunda-feira | C12: Semana 3 (12/01–17/01) | D12: Segunda – Produção & Programação | E12: Negociação sem improviso: valor antes do preço | F12: Gestão Comercial | G12: Growth | H12: Cupons/HUB | I12: Ativar cupom de CAMPANHA (7 dias) e atualizar links /go/* | J12: Crie cupom campanha na Udemy (7 dias) para o(s) curso(s) foco. Atualize targets no Redirection. | K12: Udemy Instructor + WordPress/Redirection | L12: CTA em todos os conteúdos → /trilhas | M12: Campanha ativa esta semana. Garanta que todos os CTAs usem cupom correto via /go/. | N12: 35 | O12: Alta | P12: Matrículas por cupom | Q12: A fazer

Sheet Temas Semanais
A1: Semana (início) | B1: Campanha? | C1: Tema macro | D1: CTA foco | E1: Ângulo Financeiro | F1: Ângulo Negociação/Vendas | G1: Ângulo Gestão Comercial
A2: 05/01/2026 | B2: Não | C2: Seu DRE é um dedo-duro: o que ele revela em 15 min | D2: /trilhas (botão DRE) + /go/dre | E2: Financeiro: 3 sinais no DRE que indicam onde mexer | F2: Negociação/Vendas: como DRE e margem mudam sua conversa de preço | G2: Gestão Comercial: KPI de DRE que orienta meta e comissão
A3: 12/01/2026 | B3: Sim | C3: Negociação sem improviso: valor antes do preço | D3: /trilhas (botão Negociação) + /go/negociacao | E3: Financeiro: concessões viram custo (como medir) | F3: Negociação/Vendas: 5 perguntas para subir valor percebido | G3: Gestão Comercial: ritual de preparação para negociar (time)
A4: 19/01/2026 | B4: Sim | C4: Gestão de loja para PMEs: giro, margem e rotina | D4: /trilhas (botão Varejo) + /go/varejo | E4: Financeiro: giro x margem (impacto no caixa) | F4: Negociação/Vendas: abordagem no balcão e upsell sem pressão | G4: Gestão Comercial: rotina diária/semana de loja que dá resultado
A5: 26/01/2026 | B5: Sim | C5: Execução comercial em 7 dias: pare de planejar e comece a rodar | D5: /trilhas (botão JBP) + /go/jbpgestores | E5: Financeiro: metas que cabem no caixa (ex.: entradas/saídas) | F5: Negociação/Vendas: cadência de follow-up que aumenta conversão | G5: Gestão Comercial: 7 dias de rituais (pipeline, visitas, revisão)
A6: 02/02/2026 | B6: Não | C6: Fluxo de caixa: previsibilidade em 15 minutos por semana | D6: /trilhas (botão Fluxo de Caixa) + /go/fc | E6: Financeiro: previsão vs realizado (3 ajustes) | F6: Negociação/Vendas: prazo, forma de pagamento e condições (como negociar) | G6: Gestão Comercial: rotina de cobrança e follow-up com método
A7: 09/02/2026 | B7: Sim | C7: Trilha Finanças do Gestor: do lucro ao caixa (sem enrolação) | D7: /trilhas (Trilha Finanças) + /go/dre | E7: Financeiro: sequência DRE → Caixa (como aplicar) | F7: Negociação/Vendas: como preço e margem se sustentam no caixa | G7: Gestão Comercial: metas financeiras traduzidas em metas comerciais
A8: 16/02/2026 | B8: Não | C8: Objeções: investigue antes de responder (e venda melhor) | D8: /trilhas (botão Escuta) + /go/escuta | E8: Financeiro: objeções por preço x objeções por risco (impacto em desconto) | F8: Negociação/Vendas: matriz rápida de objeções + perguntas | G8: Gestão Comercial: como treinar o time com roleplay e métricas
A9: 23/02/2026 | B9: Sim | C9: Trilha Negociação: método, prática e resultados em vendas | D9: /trilhas (Trilha Negociação) + /go/negociacao | E9: Financeiro: custo de desconto (quanto você perde) | F9: Negociação/Vendas: script de 7 passos para conduzir conversa | G9: Gestão Comercial: coaching de negociação (cadência semanal)
A10: 02/03/2026 | B10: Não | C10: Gestão comercial na prática: metas, indicadores e cadência | D10: /trilhas (botão JBP) + /go/jbp | E10: Financeiro: indicadores comerciais que protegem o caixa | F10: Negociação/Vendas: pipeline e conversão por etapa | G10: Gestão Comercial: reunião semanal de resultados (roteiro)
A11: 09/03/2026 | B11: Sim | C11: Trilha do Gestor: DRE + Caixa + Varejo (combo que resolve) | D11: /trilhas (Trilha Finanças + Varejo) + /go/dre | E11: Financeiro: modelo de leitura semanal (DRE/caixa) | F11: Negociação/Vendas: como defender preço com dados e valor | G11: Gestão Comercial: execução em loja e time (rotinas)
A12: 16/03/2026 | B12: Não | C12: Precificação e markup sem matemática chata (PME) | D12: /trilhas (curso Precificação) + /go/precificacao | E12: Financeiro: markup, margem e contribuição (o básico que decide) | F12: Negociação/Vendas: como apresentar preço sem pedir desculpas | G12: Gestão Comercial: política de desconto e alçadas
... A14: 30/03/2026 | B14: Não | C14: Checklist trimestral do gestor: revisão + plano do próximo trimestre | D14: /trilhas (todas as trilhas) + /trilhas | E14: Financeiro: revisão de DRE/caixa do trimestre (passo a passo) | F14: Negociação/Vendas: revisão de conversão e objeções (lições) | G14: Gestão Comercial: plano de 90 dias (cadência e projetos)

Sheet Regras Operacionais
A1: Regra operacional semanal (modelo)
A3: Como usar este calendário
A4: Você trabalha com 1 tema macro por semana e 3 ângulos (Financeiro, Negociação/Vendas, Gestão Comercial). A semana inteira aponta para 1 CTA principal: phdonassolo.com/trilhas.
A5: Segunda – Produção & Programação: produzir o pacote completo da semana e deixar tudo agendado. (YouTube vídeo longo + 2 shorts, LinkedIn 2 posts + 1 carrossel, IG/FB reaproveitado). Checar links /go e CTAs. Se for semana de campanha, ativar cupom CAMPANHA (7 dias) e atualizar /go/*.
A6: Terça – Udemy & Alcance: Q&A + avaliações (SLA <24h). Enviar 1 anúncio educacional (sem venda) no curso mais alinhado ao tema. 20 min de comentários estratégicos no LinkedIn.
A7: Quarta – Métricas & Cupons: atualizar KPIs (Udemy, GA4, redes). Gestão de cupons (BASE/CAMPANHA/RECUPERAÇÃO). Se campanha ativa: 1 e-mail promocional no meio da janela (respeitar limites).
A8: Quinta – Relacionamento & Qualidade: responder comentários/DMs (LI/YT). Fazer 1 melhoria incremental no curso foco (landing page, materiais, aula-isca).
A9: Sexta – Análise & Ajustes: revisão semanal (o que funcionou e por quê). Ajustar HUB /trilhas e backlog. Se campanha: última chamada + cupom RECUPERAÇÃO 48h (sem trabalhar domingo).
A10: Sábado – Planejamento: fechar tema macro + 3 ângulos + CTA da próxima semana. Rascunhar roteiro do vídeo, hooks dos posts e estrutura do carrossel. Planejar cupons e tarefas Udemy da semana.

Sheet Listas
A1: Status | B1: Prioridade | C1: Categoria | D1: Ângulo/Trilha
A2: A fazer | B2: Alta | C2: Setup | D2: Financeiro
A3: Fazendo | B3: Média | C3: Conteúdo | D3: Negociação & Vendas
A4: Feito | B4: Baixa | C4: Operação | D4: Gestão Comercial
C5: Growth | D5: Transversal (3 ângulos)
C6: Planejamento | D6: Transversal (planejar 3 ângulos)
D7: Transversal

Sheet DASH
B4: A fazer | C4: =COUNTIF(Tabela1[Status],DASH!B4) -> 238
B5: Fazendo | C5: =COUNTIF(Tabela1[Status],DASH!B5) -> 1
B6: Feito | C6: =COUNTIF(Tabela1[Status],DASH!B6) -> 3
I7: por prioridade | K7: Alta | L7: Média
B8: Em atraso | C8: =COUNTIFS(Tabela1[Status], "<>Feito", Tabela1[Data], "<="&TODAY()) -> 63 | D8: diferente de feito e data <= hoje | K8: =COUNTIFS(Tabela1[Status], "<>Feito", Tabela1[Data], "<="&TODAY(),Tabela1[Prioridade], "=Alta") -> 47 | L8: =COUNTIFS(Tabela1[Status], "<>Feito", Tabela1[Data], "<="&TODAY(),Tabela1[Prioridade], "=Média") -> 12
B9: Concluir neste mês | C9: =COUNTIFS('Plano Diário'!$Q:$Q,"<>Feito",'Plano Diário'!$A:$A,">="&DATE(YEAR(TODAY()),MONTH(TODAY()),1),'Plano Diário'!$A:$A,"<="&EOMONTH(TODAY(),0)) -> 84 | D9: diferente de feito e mês = mês atual | K9: =COUNTIFS('Plano Diário'!$Q:$Q,"<>Feito",'Plano Diário'!$A:$A,">="&DATE(YEAR(TODAY()),MONTH(TODAY()),1),'Plano Diário'!$A:$A,"<="&EOMONTH(TODAY(),0),'Plano Diário'!$O:$O,"Alta") -> 66 | L9: =COUNTIFS('Plano Diário'!$Q:$Q,"<>Feito",'Plano Diário'!$A:$A,">="&DATE(YEAR(TODAY()),MONTH(TODAY()),1),'Plano Diário'!$A:$A,"<="&EOMONTH(TODAY(),0),'Plano Diário'!$O:$O,"Média") -> 18
B10: Próximos meses | C10: =COUNTIFS('Plano Diário'!$Q:$Q,"<>Feito",'Plano Diário'!$A:$A,">"&EOMONTH(TODAY(),0)) -> 155 | D10: diferente de feito e mês > mês atual | K10: =COUNTIFS('Plano Diário'!$Q:$Q,"<>Feito",'Plano Diário'!$A:$A,">"&EOMONTH(TODAY(),0),'Plano Diário'!$O:$O,"Alta") -> 114 | L10: =COUNTIFS('Plano Diário'!$Q:$Q,"<>Feito",'Plano Diário'!$A:$A,">"&EOMONTH(TODAY(),0),'Plano Diário'!$O:$O,"Média") -> 41
